Workbook
Name ListaDepartamentos: Funcionarios!$I$2:$I$7

Sheet Editavel
A1: Modelo de Cálculo de Comissão e Bonificação
A3: Comissão Total | B3: 0
A4: Bonificação Total | B4: 35629.21
A5: Percentual via cartão | B5: 0.8
A6: Total Bruto | B6: =B3+B4 -> 35629.21
A8: Descrição | B8: Base | C8: % | D8: Dedução
A9: Convenção (20%) | B9: =B6 -> 35629.21 | C9: 0.2 | D9: =B9*C9 -> 7125.842
A10: Imposto (12% sobre saldo pós convenção) | B10: =B6-D9 -> 28503.368 | C10: 0.12 | D10: =B10*C10 -> 3420.4042
A11: Taxa Cartão (2% de percentual via cartão) | B11: =B6*$B$5 -> 28503.368 | C11: 0.02 | D11: =B11*C11 -> 570.06736
A16: Total de Deduções | B16: =SUM(D9:D11) -> 11116.314
A17: Saldo pós deduções | B17: =B6-B16 -> 24512.896
A18: Líquido para pagamento | B18: =B6-B16-B19-B20-SUM(Funcionarios!$F$2:$F$191)-SUM(Departamentos!$B:$B) -> 24512.896
A20: Descontos extras (perdas/punições) | B20: 0
A21: Bônus departamentais aplicados | B21: =SUM(Departamentos!$B:$B) -> 0
A24: Pontuação | B24: Base | C24: % da Comissão | D24: Valor
A25: Ponto 1 | B25: =$B$18 -> 24512.896 | C25: 0.1 | D25: =B25*C25 -> 2451.2896
A26: Ponto 2 | B26: =$B$18 -> 24512.896 | C26: 0.3 | D26: =B26*C26 -> 7353.8689
A27: Ponto 3 | B27: =$B$18 -> 24512.896 | C27: 0.33 | D27: =B27*C27 -> 8089.2558
A28: Ponto 4 | B28: =$B$18 -> 24512.896 | C28: 0.17 | D28: =B28*C28 -> 4167.1924
A29: Ponto 5 | B29: =$B$18 -> 24512.896 | C29: 0.1 | D29: =B29*C29 -> 2451.2896
A30: Total Percentual | C30: =SUM(C25:C29) -> 1
A31: Total Distribuído | D31: =SUM(D25:D29) -> 24512.896
A32: Líquido restante após distribuição | B32: =$B$17-D31 -> 0
A33: Diferença de reconciliação | B33: =$B$17-SUM(Distribuicao!$G$2:$G$201) -> 2002.1754

Sheet Funcionarios
A1: Nome | B1: Departamento | C1: DataAdmissao | D1: Pontos | E1: DeducaoIndividual | F1: BonificacaoIndividual | G1: DiasTrabalhados | I1: Departamentos | K1: Resumo
A2: Adailton dos santos oliveira | B2: serviço | C2: 43586 | D2: 3 | G2: 30 | I2: recepção | K2: Total de Funcionários | L2: =COUNTA($A$2:$A$191) -> 45 | M2: Percentual | N2: =1 -> 1
A3: Ademir Generali | B3: manutenção | C3: 36526 | D3: 3 | G3: 30 | I3: cozinha
A4: Adriana Ferreira Dos Santos | B4: cozinha | C4: 45627 | D4: 3 | G4: 30 | I4: serviço | K4: Por Pontuação
A5: Adriana Santos Do Nascimento | B5: governança | C5: 45901 | D5: 2 | G5: 30 | I5: manutenção | K5: Ponto 1 | L5: =COUNTIF($D$2:$D$191,1) -> 0 | M5: =IF($L$2>0,L5/$L$2,0) -> 0
A6: Alan Paiva Lima | B6: recepção | C6: 45597 | D6: 3 | G6: 30 | I6: governança | K6: Ponto 2 | L6: =COUNTIF($D$2:$D$191,2) -> 21 | M6: =IF($L$2>0,L6/$L$2,0) -> 0.46666667
A7: Andrea Minervino De Melo Vasconcelos | B7: governança | C7: 45536 | D7: 4 | G7: 30 | I7: controle de perdas | K7: Ponto 3 | L7: =COUNTIF($D$2:$D$191,3) -> 12 | M7: =IF($L$2>0,L7/$L$2,0) -> 0.26666667
A8: Aurinete maria de oliveira | B8: cozinha | C8: 43497 | D8: 4 | G8: 30 | K8: Ponto 4 | L8: =COUNTIF($D$2:$D$191,4) -> 7 | M8: =IF($L$2>0,L8/$L$2,0) -> 0.15555556
A9: Bartolomeu Leandro René de Araujo | B9: serviço | C9: 45901 | D9: 2 | G9: 30 | K9: Ponto 5 | L9: =COUNTIF($D$2:$D$191,5) -> 5 | M9: =IF($L$2>0,L9/$L$2,0) -> 0.11111111
A10: Bruno Ruanderson Mendes | B10: recepção | C10: 45717 | D10: 3 | G10: 30
A11: Carlos Eduardo Carneiro da Silva | B11: controle de perdas | C11: 44409 | D11: 5 | G11: 30 | K11: Por Departamento
A12: Cicera maria da Silva | B12: cozinha | C12: 45231 | D12: 5 | G12: 30 | K12: recepção | L12: =COUNTIF($B$2:$B$191,"recepção") -> 6 | M12: =IF($L$2>0,L12/$L$2,0) -> 0.13333333
A13: Cintia Raquel Da Silva | B13: cozinha | C13: 44866 | D13: 4 | G13: 30 | K13: cozinha | L13: =COUNTIF($B$2:$B$191,"cozinha") -> 11 | M13: =IF($L$2>0,L13/$L$2,0) -> 0.24444444
A14: Clebio Alves de Moura | B14: serviço | C14: 45931 | D14: 2 | G14: 30 | K14: serviço | L14: =COUNTIF($B$2:$B$191,"serviço") -> 15 | M14: =IF($L$2>0,L14/$L$2,0) -> 0.33333333
A15: Daniel Luiz De Lima | B15: manutenção | C15: 45962 | D15: 2 | G15: 30 | K15: manutenção | L15: =COUNTIF($B$2:$B$191,"manutenção") -> 6 | M15: =IF($L$2>0,L15/$L$2,0) -> 0.13333333
A16: Danilo Cesar Silva Lima | B16: serviço | C16: 45566 | D16: 3 | G16: 30 | K16: governança | L16: =COUNTIF($B$2:$B$191,"governança") -> 5 | M16: =IF($L$2>0,L16/$L$2,0) -> 0.11111111
A17: Dina Priscila dos Santos Nunes | B17: governança | C17: 45627 | D17: 3 | G17: 30 | K17: controle de perdas | L17: =COUNTIF($B$2:$B$191,"controle de perdas") -> 2 | M17: =IF($L$2>0,L17/$L$2,0) -> 0.044444444
A18: Elenilda Dos Santos Da Silva | B18: cozinha | C18: 45931 | D18: 2 | G18: 30
A19: Eliete Maria Dos Santos Da Silva | B19: cozinha | C19: 46296 | D19: 2 | G19: 16
A20: Erick Manoel Santos Do Nascimento | B20: serviço | C20: 45992 | D20: 2 | G20: 10
A21: Erique Neves Cavalcanti | B21: serviço | C21: 45931 | D21: 2 | G21: 30
A22: Filipe da silva assis | B22: serviço | C22: 45261 | D22: 4 | G22: 30
A23: Generina Jovelina Da Silva | B23: governança | C23: 45261 | D23: 3 | G23: 30
A24: Gilvan Santos de Brito | B24: manutenção | C24: 45597 | D24: 5 | G24: 30
A25: Guilherme Henrique da Silva | B25: serviço | C25: 44835 | D25: 4 | G25: 30
A26: Iraquitan De Freitas Lima Junior | B26: recepção | C26: 45566 | D26: 5 | E26: 468.72 | G26: 30
A27: Jaqueline Maria Santos da Silva | B27: governança | C27: 45931 | D27: 2 | G27: 30
A28: Jose Antunes Rocha e Silva do Nascimento | B28: serviço | C28: 45992 | D28: 5 | E28: 198.07 | G28: 15
A29: Jose Cicero Santos Acioli de Melo | B29: manutenção | C29: 46025 | D29: 2 | G29: 12
A30: José Edson França dos Santos | B30: serviço | C30: 45992 | D30: 2 | G30: 30
A31: José Gomes Da Silva | B31: serviço | C31: 44409 | D31: 3 | G31: 30
A32: José Henrique Lucena da Silva | B32: serviço | C32: 45931 | D32: 2 | G32: 30
A33: Jose Roberto Da Silva | B33: recepção | C33: 46368 | D33: 2 | G33: 20
A34: Josenice Maria De Oliveira | B34: cozinha | C34: 44409 | D34: 3 | G34: 30
A35: Kayke Emanoel de Lima | B35: serviço | C35: 45992 | D35: 2 | G35: 30
A36: Lindinalva Maria Pereira | B36: cozinha | C36: 45870 | D36: 2 | G36: 30
A37: Luciano Aleixo Dos Santos | B37: manutenção | C37: 46260 | D37: 2 | G37: 16
A38: Luiz Carlos Rodrigues Dos Santos | B38: manutenção | C38: 45839 | D38: 2 | G38: 30
A39: Luiz Eduardo Carneiro da Silva | B39: recepção | C39: 44713 | D39: 4 | G39: 30
A40: Maria Nadier Da Silva | B40: cozinha | C40: 45839 | D40: 2 | G40: 30
...

Sheet Departamentos
A1: recepção
A2: nome | B2: valor
B3: 0 | C3: recepção
B4: 0 | C4: recepção
B5: 0 | C5: recepção
B6: 0 | C6: recepção
B7: 0 | C7: recepção
B8: 0 | C8: recepção
B9: 0 | C9: recepção
B10: 0 | C10: recepção
B11: 0 | C11: recepção
B12: 0 | C12: recepção
A13: cozinha
A14: nome | B14: valor
B15: 0 | C15: cozinha
B16: 0 | C16: cozinha
B17: 0 | C17: cozinha
B18: 0 | C18: cozinha
B19: 0 | C19: cozinha
B20: 0 | C20: cozinha
B21: 0 | C21: cozinha
B22: 0 | C22: cozinha
B23: 0 | C23: cozinha
B24: 0 | C24: cozinha
A25: serviço
A26: nome | B26: valor
B27: 0 | C27: serviço
B28: 0 | C28: serviço
B29: 0 | C29: serviço
B30: 0 | C30: serviço
B31: 0 | C31: serviço
B32: 0 | C32: serviço
B33: 0 | C33: serviço
B34: 0 | C34: serviço
B35: 0 | C35: serviço
B36: 0 | C36: serviço
A37: manutenção
A38: nome | B38: valor
B39: 0 | C39: manutenção
B40: 0 | C40: manutenção
...

Sheet Distribuicao
A1: Funcionário | B1: Departamento | C1: Cotas por pontos | D1: Bônus Depto | E1: Bonificação Individual | F1: Deducao Individual | G1: Total Funcionário | H1: Total Distribuído | I1: =SUM($G$2:$G$201) -> 22510.721 | J1: Resumo por Departamento
A2: =Funcionarios!A2 -> Adailton dos santos oliveira | B2: =Funcionarios!B2 -> serviço | C2: =(IF(AND(Funcionarios!D2>=1,COUNTIF(Funcionarios!$D$2:$D$191,">=1")>0),(Editavel!$B$17-SUM(Departamentos!$B:$B)-SUM(Funcionarios!$F$2:$F$191))*Editavel!$C$25/COUNTIF(Funcionarios!$D$2:$D$191,">=1"),0)+IF(AND(Funcionarios!D2>=2,COUNTIF(Funcionarios!$D$2:$D$191,">=2")>0),(Editavel!$B$17-SUM(Departamentos!$B:$B)-SUM(Funcionarios!$F$2:$F$191))*Editavel!$C$26/COUNTIF(Funcionarios!$D$2:$D$191,">=2"),0)+IF(AND(Funcionarios!D2>=3,COUNTIF(Funcionarios!$D$2:$D$191,">=3")>0),(Editavel!$B$17-SUM(Departamentos!$B:$B)-SUM(Funcionarios!$F$2:$F$191))*Editavel!$C$27/COUNTIF(Funcionarios!$D$2:$D$191,">=3"),0)+IF(AND(Funcionarios!D2>=4,COUNTIF(Funcionarios!$D$2:$D$191,">=4")>0),(Editavel!$B$17-SUM(Departamentos!$B:$B)-SUM(Funcionarios!$F$2:$F$191))*Editavel!$C$28/COUNTIF(Funcionarios!$D$2:$D$191,">=4"),0)+IF(AND(Funcionarios!D2>=5,COUNTIF(Funcionarios!$D$2:$D$191,">=5")>0),(Editavel!$B$17-SUM(Departamentos!$B:$B)-SUM(Funcionarios!$F$2:$F$191))*Editavel!$C$29/COUNTIF(Funcionarios!$D$2:$D$191,">=5"),0))*IF(Funcionarios!G2>0,Funcionarios!G2/30,1) -> 554.94474 | D2: =IF(COUNTIF(Funcionarios!$B$2:$B$191,Funcionarios!B2)>0,SUMIFS(Departamentos!$B:$B,Departamentos!$C:$C,Funcionarios!B2)/COUNTIF(Funcionarios!$B$2:$B$191,Funcionarios!B2)*IF(Funcionarios!G2>0,Funcionarios!G2/30,1),0) -> 0 | E2: =Funcionarios!$F2 -> 0 | F2: =Funcionarios!$E2 -> 0 | G2: =MAX(C2+D2+E2-F2,0) -> 554.94474 | J2: Departamento | K2: Total Distribuído | L2: Qtd Funcionários
A3: =Funcionarios!A3 -> Ademir Generali | B3: =Funcionarios!B3 -> manutenção | C3: =(IF(AND(Funcionarios!D3>=1,COUNTIF(Funcionarios!$D$2:$D$191,">=1")>0),(Editavel!$B$17-SUM(Departamentos!$B:$B)-SUM(Funcionarios!$F$2:$F$191))*Editavel!$C$25/COUNTIF(Funcionarios!$D$2:$D$191,">=1"),0)+IF(AND(Funcionarios!D3>=2,COUNTIF(Funcionarios!$D$2:$D$191,">=2")>0),(Editavel!$B$17-SUM(Departamentos!$B:$B)-SUM(Funcionarios!$F$2:$F$191))*Editavel!$C$26/COUNTIF(Funcionarios!$D$2:$D$191,">=2"),0)+IF(AND(Funcionarios!D3>=3,COUNTIF(Funcionarios!$D$2:$D$191,">=3")>0),(Editavel!$B$17-SUM(Departamentos!$B:$B)-SUM(Funcionarios!$F$2:$F$191))*Editavel!$C$27/COUNTIF(Funcionarios!$D$2:$D$191,">=3"),0)+IF(AND(Funcionarios!D3>=4,COUNTIF(Funcionarios!$D$2:$D$191,">=4")>0),(Editavel!$B$17-SUM(Departamentos!$B:$B)-SUM(Funcionarios!$F$2:$F$191))*Editavel!$C$28/COUNTIF(Funcionarios!$D$2:$D$191,">=4"),0)+IF(AND(Funcionarios!D3>=5,COUNTIF(Funcionarios!$D$2:$D$191,">=5")>0),(Editavel!$B$17-SUM(Departamentos!$B:$B)-SUM(Funcionarios!$F$2:$F$191))*Editavel!$C$29/COUNTIF(Funcionarios!$D$2:$D$191,">=5"),0))*IF(Funcionarios!G3>0,Funcionarios!G3/30,1) -> 554.94474 | D3: =IF(COUNTIF(Funcionarios!$B$2:$B$191,Funcionarios!B3)>0,SUMIFS(Departamentos!$B:$B,Departamentos!$C:$C,Funcionarios!B3)/COUNTIF(Funcionarios!$B$2:$B$191,Funcionarios!B3)*IF(Funcionarios!G3>0,Funcionarios!G3/30,1),0) -> 0 | E3: =Funcionarios!$F3 -> 0 | F3: =Funcionarios!$E3 -> 0 | G3: =MAX(C3+D3+E3-F3,0) -> 554.94474 | J3: recepção | K3: =SUMIF($B:$B,J3,$G:$G) -> 3983.3213 | L3: =COUNTIF($B:$B,J3) -> 6
A4: =Funcionarios!A4 -> Adriana Ferreira Dos Santos | B4: =Funcionarios!B4 -> cozinha | C4: =(IF(AND(Funcionarios!D4>=1,COUNTIF(Funcionarios!$D$2:$D$191,">=1")>0),(Editavel!$B$17-SUM(Departamentos!$B:$B)-SUM(Funcionarios!$F$2:$F$191))*Editavel!$C$25/COUNTIF(Funcionarios!$D$2:$D$191,">=1"),0)+IF(AND(Funcionarios!D4>=2,COUNTIF(Funcionarios!$D$2:$D$191,">=2")>0),(Editavel!$B$17-SUM(Departamentos!$B:$B)-SUM(Funcionarios!$F$2:$F$191))*Editavel!$C$26/COUNTIF(Funcionarios!$D$2:$D$191,">=2"),0)+IF(AND(Funcionarios!D4>=3,COUNTIF(Funcionarios!$D$2:$D$191,">=3")>0),(Editavel!$B$17-SUM(Departamentos!$B:$B)-SUM(Funcionarios!$F$2:$F$191))*Editavel!$C$27/COUNTIF(Funcionarios!$D$2:$D$191,">=3"),0)+IF(AND(Funcionarios!D4>=4,COUNTIF(Funcionarios!$D$2:$D$191,">=4")>0),(Editavel!$B$17-SUM(Departamentos!$B:$B)-SUM(Funcionarios!$F$2:$F$191))*Editavel!$C$28/COUNTIF(Funcionarios!$D$2:$D$191,">=4"),0)+IF(AND(Funcionarios!D4>=5,COUNTIF(Funcionarios!$D$2:$D$191,">=5")>0),(Editavel!$B$17-SUM(Departamentos!$B:$B)-SUM(Funcionarios!$F$2:$F$191))*Editavel!$C$29/COUNTIF(Funcionarios!$D$2:$D$191,">=5"),0))*IF(Funcionarios!G4>0,Funcionarios!G4/30,1) -> 554.94474 | D4: =IF(COUNTIF(Funcionarios!$B$2:$B$191,Funcionarios!B4)>0,SUMIFS(Departamentos!$B:$B,Departamentos!$C:$C,Funcionarios!B4)/COUNTIF(Funcionarios!$B$2:$B$191,Funcionarios!B4)*IF(Funcionarios!G4>0,Funcionarios!G4/30,1),0) -> 0 | E4: =Funcionarios!$F4 -> 0 | F4: =Funcionarios!$E4 -> 0 | G4: =MAX(C4+D4+E4-F4,0) -> 554.94474 | J4: cozinha | K4: =SUMIF($B:$B,J4,$G:$G) -> 5849.5034 | L4: =COUNTIF($B:$B,J4) -> 11
A5: =Funcionarios!A5 -> Adriana Santos Do Nascimento | B5: =Funcionarios!B5 -> governança | C5: =(IF(AND(Funcionarios!D5>=1,COUNTIF(Funcionarios!$D$2:$D$191,">=1")>0),(Editavel!$B$17-SUM(Departamentos!$B:$B)-SUM(Funcionarios!$F$2:$F$191))*Editavel!$C$25/COUNTIF(Funcionarios!$D$2:$D$191,">=1"),0)+IF(AND(Funcionarios!D5>=2,COUNTIF(Funcionarios!$D$2:$D$191,">=2")>0),(Editavel!$B$17-SUM(Departamentos!$B:$B)-SUM(Funcionarios!$F$2:$F$191))*Editavel!$C$26/COUNTIF(Funcionarios!$D$2:$D$191,">=2"),0)+IF(AND(Funcionarios!D5>=3,COUNTIF(Funcionarios!$D$2:$D$191,">=3")>0),(Editavel!$B$17-SUM(Departamentos!$B:$B)-SUM(Funcionarios!$F$2:$F$191))*Editavel!$C$27/COUNTIF(Funcionarios!$D$2:$D$191,">=3"),0)+IF(AND(Funcionarios!D5>=4,COUNTIF(Funcionarios!$D$2:$D$191,">=4")>0),(Editavel!$B$17-SUM(Departamentos!$B:$B)-SUM(Funcionarios!$F$2:$F$191))*Editavel!$C$28/COUNTIF(Funcionarios!$D$2:$D$191,">=4"),0)+IF(AND(Funcionarios!D5>=5,COUNTIF(Funcionarios!$D$2:$D$191,">=5")>0),(Editavel!$B$17-SUM(Departamentos!$B:$B)-SUM(Funcionarios!$F$2:$F$191))*Editavel!$C$29/COUNTIF(Funcionarios!$D$2:$D$191,">=5"),0))*IF(Funcionarios!G5>0,Funcionarios!G5/30,1) -> 217.89241 | D5: =IF(COUNTIF(Funcionarios!$B$2:$B$191,Funcionarios!B5)>0,SUMIFS(Departamentos!$B:$B,Departamentos!$C:$C,Funcionarios!B5)/COUNTIF(Funcionarios!$B$2:$B$191,Funcionarios!B5)*IF(Funcionarios!G5>0,Funcionarios!G5/30,1),0) -> 0 | E5: =Funcionarios!$F5 -> 0 | F5: =Funcionarios!$E5 -> 0 | G5: =MAX(C5+D5+E5-F5,0) -> 217.89241 | J5: serviço | K5: =SUMIF($B:$B,J5,$G:$G) -> 6033.0856 | L5: =COUNTIF($B:$B,J5) -> 15
A6: =Funcionarios!A6 -> Alan Paiva Lima | B6: =Funcionarios!B6 -> recepção | C6: =(IF(AND(Funcionarios!D6>=1,COUNTIF(Funcionarios!$D$2:$D$191,">=1")>0),(Editavel!$B$17-SUM(Departamentos!$B:$B)-SUM(Funcionarios!$F$2:$F$191))*Editavel!$C$25/COUNTIF(Funcionarios!$D$2:$D$191,">=1"),0)+IF(AND(Funcionarios!D6>=2,COUNTIF(Funcionarios!$D$2:$D$191,">=2")>0),(Editavel!$B$17-SUM(Departamentos!$B:$B)-SUM(Funcionarios!$F$2:$F$191))*Editavel!$C$26/COUNTIF(Funcionarios!$D$2:$D$191,">=2"),0)+IF(AND(Funcionarios!D6>=3,COUNTIF(Funcionarios!$D$2:$D$191,">=3")>0),(Editavel!$B$17-SUM(Departamentos!$B:$B)-SUM(Funcionarios!$F$2:$F$191))*Editavel!$C$27/COUNTIF(Funcionarios!$D$2:$D$191,">=3"),0)+IF(AND(Funcionarios!D6>=4,COUNTIF(Funcionarios!$D$2:$D$191,">=4")>0),(Editavel!$B$17-SUM(Departamentos!$B:$B)-SUM(Funcionarios!$F$2:$F$191))*Editavel!$C$28/COUNTIF(Funcionarios!$D$2:$D$191,">=4"),0)+IF(AND(Funcionarios!D6>=5,COUNTIF(Funcionarios!$D$2:$D$191,">=5")>0),(Editavel!$B$17-SUM(Departamentos!$B:$B)-SUM(Funcionarios!$F$2:$F$191))*Editavel!$C$29/COUNTIF(Funcionarios!$D$2:$D$191,">=5"),0))*IF(Funcionarios!G6>0,Funcionarios!G6/30,1) -> 554.94474 | D6: =IF(COUNTIF(Funcionarios!$B$2:$B$191,Funcionarios!B6)>0,SUMIFS(Departamentos!$B:$B,Departamentos!$C:$C,Funcionarios!B6)/COUNTIF(Funcionarios!$B$2:$B$191,Funcionarios!B6)*IF(Funcionarios!G6>0,Funcionarios!G6/30,1),0) -> 0 | E6: =Funcionarios!$F6 -> 0 | F6: =Funcionarios!$E6 -> 0 | G6: =MAX(C6+D6+E6-F6,0) -> 554.94474 | J6: manutenção | K6: =SUMIF($B:$B,J6,$G:$G) -> 2586.5645 | L6: =COUNTIF($B:$B,J6) -> 6
A7: =Funcionarios!A7 -> Andrea Minervino De Melo Vasconcelos | B7: =Funcionarios!B7 -> governança | C7: =(IF(AND(Funcionarios!D7>=1,COUNTIF(Funcionarios!$D$2:$D$191,">=1")>0),(Editavel!$B$17-SUM(Departamentos!$B:$B)-SUM(Funcionarios!$F$2:$F$191))*Editavel!$C$25/COUNTIF(Funcionarios!$D$2:$D$191,">=1"),0)+IF(AND(Funcionarios!D7>=2,COUNTIF(Funcionarios!$D$2:$D$191,">=2")>0),(Editavel!$B$17-SUM(Departamentos!$B:$B)-SUM(Funcionarios!$F$2:$F$191))*Editavel!$C$26/COUNTIF(Funcionarios!$D$2:$D$191,">=2"),0)+IF(AND(Funcionarios!D7>=3,COUNTIF(Funcionarios!$D$2:$D$191,">=3")>0),(Editavel!$B$17-SUM(Departamentos!$B:$B)-SUM(Funcionarios!$F$2:$F$191))*Editavel!$C$27/COUNTIF(Funcionarios!$D$2:$D$191,">=3"),0)+IF(AND(Funcionarios!D7>=4,COUNTIF(Funcionarios!$D$2:$D$191,">=4")>0),(Editavel!$B$17-SUM(Departamentos!$B:$B)-SUM(Funcionarios!$F$2:$F$191))*Editavel!$C$28/COUNTIF(Funcionarios!$D$2:$D$191,">=4"),0)+IF(AND(Funcionarios!D7>=5,COUNTIF(Funcionarios!$D$2:$D$191,">=5")>0),(Editavel!$B$17-SUM(Departamentos!$B:$B)-SUM(Funcionarios!$F$2:$F$191))*Editavel!$C$29/COUNTIF(Funcionarios!$D$2:$D$191,">=5"),0))*IF(Funcionarios!G7>0,Funcionarios!G7/30,1) -> 902.21077 | D7: =IF(COUNTIF(Funcionarios!$B$2:$B$191,Funcionarios!B7)>0,SUMIFS(Departamentos!$B:$B,Departamentos!$C:$C,Funcionarios!B7)/COUNTIF(Funcionarios!$B$2:$B$191,Funcionarios!B7)*IF(Funcionarios!G7>0,Funcionarios!G7/30,1),0) -> 0 | E7: =Funcionarios!$F7 -> 0 | F7: =Funcionarios!$E7 -> 0 | G7: =MAX(C7+D7+E7-F7,0) -> 902.21077 | J7: governança | K7: =SUMIF($B:$B,J7,$G:$G) -> 2447.8851 | L7: =COUNTIF($B:$B,J7) -> 5
A8: =Funcionarios!A8 -> Aurinete maria de oliveira | B8: =Funcionarios!B8 -> cozinha | C8: =(IF(AND(Funcionarios!D8>=1,COUNTIF(Funcionarios!$D$2:$D$191,">=1")>0),(Editavel!$B$17-SUM(Departamentos!$B:$B)-SUM(Funcionarios!$F$2:$F$191))*Editavel!$C$25/COUNTIF(Funcionarios!$D$2:$D$191,">=1"),0)+IF(AND(Funcionarios!D8>=2,COUNTIF(Funcionarios!$D$2:$D$191,">=2")>0),(Editavel!$B$17-SUM(Departamentos!$B:$B)-SUM(Funcionarios!$F$2:$F$191))*Editavel!$C$26/COUNTIF(Funcionarios!$D$2:$D$191,">=2"),0)+IF(AND(Funcionarios!D8>=3,COUNTIF(Funcionarios!$D$2:$D$191,">=3")>0),(Editavel!$B$17-SUM(Departamentos!$B:$B)-SUM(Funcionarios!$F$2:$F$191))*Editavel!$C$27/COUNTIF(Funcionarios!$D$2:$D$191,">=3"),0)+IF(AND(Funcionarios!D8>=4,COUNTIF(Funcionarios!$D$2:$D$191,">=4")>0),(Editavel!$B$17-SUM(Departamentos!$B:$B)-SUM(Funcionarios!$F$2:$F$191))*Editavel!$C$28/COUNTIF(Funcionarios!$D$2:$D$191,">=4"),0)+IF(AND(Funcionarios!D8>=5,COUNTIF(Funcionarios!$D$2:$D$191,">=5")>0),(Editavel!$B$17-SUM(Departamentos!$B:$B)-SUM(Funcionarios!$F$2:$F$191))*Editavel!$C$29/COUNTIF(Funcionarios!$D$2:$D$191,">=5"),0))*IF(Funcionarios!G8>0,Funcionarios!G8/30,1) -> 902.21077 | D8: =IF(COUNTIF(Funcionarios!$B$2:$B$191,Funcionarios!B8)>0,SUMIFS(Departamentos!$B:$B,Departamentos!$C:$C,Funcionarios!B8)/COUNTIF(Funcionarios!$B$2:$B$191,Funcionarios!B8)*IF(Funcionarios!G8>0,Funcionarios!G8/30,1),0) -> 0 | E8: =Funcionarios!$F8 -> 0 | F8: =Funcionarios!$E8 -> 0 | G8: =MAX(C8+D8+E8-F8,0) -> 902.21077 | J8: controle de perdas | K8: =SUMIF($B:$B,J8,$G:$G) -> 1610.3611 | L8: =COUNTIF($B:$B,J8) -> 2
A9: =Funcionarios!A9 -> Bartolomeu Leandro René de Araujo | B9: =Funcionarios!B9 -> serviço | C9: =(IF(AND(Funcionarios!D9>=1,COUNTIF(Funcionarios!$D$2:$D$191,">=1")>0),(Editavel!$B$17-SUM(Departamentos!$B:$B)-SUM(Funcionarios!$F$2:$F$191))*Editavel!$C$25/COUNTIF(Funcionarios!$D$2:$D$191,">=1"),0)+IF(AND(Funcionarios!D9>=2,COUNTIF(Funcionarios!$D$2:$D$191,">=2")>0),(Editavel!$B$17-SUM(Departamentos!$B:$B)-SUM(Funcionarios!$F$2:$F$191))*Editavel!$C$26/COUNTIF(Funcionarios!$D$2:$D$191,">=2"),0)+IF(AND(Funcionarios!D9>=3,COUNTIF(Funcionarios!$D$2:$D$191,">=3")>0),(Editavel!$B$17-SUM(Departamentos!$B:$B)-SUM(Funcionarios!$F$2:$F$191))*Editavel!$C$27/COUNTIF(Funcionarios!$D$2:$D$191,">=3"),0)+IF(AND(Funcionarios!D9>=4,COUNTIF(Funcionarios!$D$2:$D$191,">=4")>0),(Editavel!$B$17-SUM(Departamentos!$B:$B)-SUM(Funcionarios!$F$2:$F$191))*Editavel!$C$28/COUNTIF(Funcionarios!$D$2:$D$191,">=4"),0)+IF(AND(Funcionarios!D9>=5,COUNTIF(Funcionarios!$D$2:$D$191,">=5")>0),(Editavel!$B$17-SUM(Departamentos!$B:$B)-SUM(Funcionarios!$F$2:$F$191))*Editavel!$C$29/COUNTIF(Funcionarios!$D$2:$D$191,">=5"),0))*IF(Funcionarios!G9>0,Funcionarios!G9/30,1) -> 217.89241 | D9: =IF(COUNTIF(Funcionarios!$B$2:$B$191,Funcionarios!B9)>0,SUMIFS(Departamentos!$B:$B,Departamentos!$C:$C,Funcionarios!B9)/COUNTIF(Funcionarios!$B$2:$B$191,Funcionarios!B9)*IF(Funcionarios!G9>0,Funcionarios!G9/30,1),0) -> 0 | E9: =Funcionarios!$F9 -> 0 | F9: =Funcionarios!$E9 -> 0 | G9: =MAX(C9+D9+E9-F9,0) -> 217.89241
A10: =Funcionarios!A10 -> Bruno Ruanderson Mendes | B10: =Funcionarios!B10 -> recepção | C10: =(IF(AND(Funcionarios!D10>=1,COUNTIF(Funcionarios!$D$2:$D$191,">=1")>0),(Editavel!$B$17-SUM(Departamentos!$B:$B)-SUM(Funcionarios!$F$2:$F$191))*Editavel!$C$25/COUNTIF(Funcionarios!$D$2:$D$191,">=1"),0)+IF(AND(Funcionarios!D10>=2,COUNTIF(Funcionarios!$D$2:$D$191,">=2")>0),(Editavel!$B$17-SUM(Departamentos!$B:$B)-SUM(Funcionarios!$F$2:$F$191))*Editavel!$C$26/COUNTIF(Funcionarios!$D$2:$D$191,">=2"),0)+IF(AND(Funcionarios!D10>=3,COUNTIF(Funcionarios!$D$2:$D$191,">=3")>0),(Editavel!$B$17-SUM(Departamentos!$B:$B)-SUM(Funcionarios!$F$2:$F$191))*Editavel!$C$27/COUNTIF(Funcionarios!$D$2:$D$191,">=3"),0)+IF(AND(Funcionarios!D10>=4,COUNTIF(Funcionarios!$D$2:$D$191,">=4")>0),(Editavel!$B$17-SUM(Departamentos!$B:$B)-SUM(Funcionarios!$F$2:$F$191))*Editavel!$C$28/COUNTIF(Funcionarios!$D$2:$D$191,">=4"),0)+IF(AND(Funcionarios!D10>=5,COUNTIF(Funcionarios!$D$2:$D$191,">=5")>0),(Editavel!$B$17-SUM(Departamentos!$B:$B)-SUM(Funcionarios!$F$2:$F$191))*Editavel!$C$29/COUNTIF(Funcionarios!$D$2:$D$191,">=5"),0))*IF(Funcionarios!G10>0,Funcionarios!G10/30,1) -> 554.94474 | D10: =IF(COUNTIF(Funcionarios!$B$2:$B$191,Funcionarios!B10)>0,SUMIFS(Departamentos!$B:$B,Departamentos!$C:$C,Funcionarios!B10)/COUNTIF(Funcionarios!$B$2:$B$191,Funcionarios!B10)*IF(Funcionarios!G10>0,Funcionarios!G10/30,1),0) -> 0 | E10: =Funcionarios!$F10 -> 0 | F10: =Funcionarios!$E10 -> 0 | G10: =MAX(C10+D10+E10-F10,0) -> 554.94474
A11: =Funcionarios!A11 -> Carlos Eduardo Carneiro da Silva | B11: =Funcionarios!B11 -> controle de perdas | C11: =(IF(AND(Funcionarios!D11>=1,COUNTIF(Funcionarios!$D$2:$D$191,">=1")>0),(Editavel!$B$17-SUM(Departamentos!$B:$B)-SUM(Funcionarios!$F$2:$F$191))*Editavel!$C$25/COUNTIF(Funcionarios!$D$2:$D$191,">=1"),0)+IF(AND(Funcionarios!D11>=2,COUNTIF(Funcionarios!$D$2:$D$191,">=2")>0),(Editavel!$B$17-SUM(Departamentos!$B:$B)-SUM(Funcionarios!$F$2:$F$191))*Editavel!$C$26/COUNTIF(Funcionarios!$D$2:$D$191,">=2"),0)+IF(AND(Funcionarios!D11>=3,COUNTIF(Funcionarios!$D$2:$D$191,">=3")>0),(Editavel!$B$17-SUM(Departamentos!$B:$B)-SUM(Funcionarios!$F$2:$F$191))*Editavel!$C$27/COUNTIF(Funcionarios!$D$2:$D$191,">=3"),0)+IF(AND(Funcionarios!D11>=4,COUNTIF(Funcionarios!$D$2:$D$191,">=4")>0),(Editavel!$B$17-SUM(Departamentos!$B:$B)-SUM(Funcionarios!$F$2:$F$191))*Editavel!$C$28/COUNTIF(Funcionarios!$D$2:$D$191,">=4"),0)+IF(AND(Funcionarios!D11>=5,COUNTIF(Funcionarios!$D$2:$D$191,">=5")>0),(Editavel!$B$17-SUM(Departamentos!$B:$B)-SUM(Funcionarios!$F$2:$F$191))*Editavel!$C$29/COUNTIF(Funcionarios!$D$2:$D$191,">=5"),0))*IF(Funcionarios!G11>0,Funcionarios!G11/30,1) -> 1392.4687 | D11: =IF(COUNTIF(Funcionarios!$B$2:$B$191,Funcionarios!B11)>0,SUMIFS(Departamentos!$B:$B,Departamentos!$C:$C,Funcionarios!B11)/COUNTIF(Funcionarios!$B$2:$B$191,Funcionarios!B11)*IF(Funcionarios!G11>0,Funcionarios!G11/30,1),0) -> 0 | E11: =Funcionarios!$F11 -> 0 | F11: =Funcionarios!$E11 -> 0 | G11: =MAX(C11+D11+E11-F11,0) -> 1392.4687
A12: =Funcionarios!A12 -> Cicera maria da Silva | B12: =Funcionarios!B12 -> cozinha | C12: =(IF(AND(Funcionarios!D12>=1,COUNTIF(Funcionarios!$D$2:$D$191,">=1")>0),(Editavel!$B$17-SUM(Departamentos!$B:$B)-SUM(Funcionarios!$F$2:$F$191))*Editavel!$C$25/COUNTIF(Funcionarios!$D$2:$D$191,">=1"),0)+IF(AND(Funcionarios!D12>=2,COUNTIF(Funcionarios!$D$2:$D$191,">=2")>0),(Editavel!$B$17-SUM(Departamentos!$B:$B)-SUM(Funcionarios!$F$2:$F$191))*Editavel!$C$26/COUNTIF(Funcionarios!$D$2:$D$191,">=2"),0)+IF(AND(Funcionarios!D12>=3,COUNTIF(Funcionarios!$D$2:$D$191,">=3")>0),(Editavel!$B$17-SUM(Departamentos!$B:$B)-SUM(Funcionarios!$F$2:$F$191))*Editavel!$C$27/COUNTIF(Funcionarios!$D$2:$D$191,">=3"),0)+IF(AND(Funcionarios!D12>=4,COUNTIF(Funcionarios!$D$2:$D$191,">=4")>0),(Editavel!$B$17-SUM(Departamentos!$B:$B)-SUM(Funcionarios!$F$2:$F$191))*Editavel!$C$28/COUNTIF(Funcionarios!$D$2:$D$191,">=4"),0)+IF(AND(Funcionarios!D12>=5,COUNTIF(Funcionarios!$D$2:$D$191,">=5")>0),(Editavel!$B$17-SUM(Departamentos!$B:$B)-SUM(Funcionarios!$F$2:$F$191))*Editavel!$C$29/COUNTIF(Funcionarios!$D$2:$D$191,">=5"),0))*IF(Funcionarios!G12>0,Funcionarios!G12/30,1) -> 1392.4687 | D12: =IF(COUNTIF(Funcionarios!$B$2:$B$191,Funcionarios!B12)>0,SUMIFS(Departamentos!$B:$B,Departamentos!$C:$C,Funcionarios!B12)/COUNTIF(Funcionarios!$B$2:$B$191,Funcionarios!B12)*IF(Funcionarios!G12>0,Funcionarios!G12/30,1),0) -> 0 | E12: =Funcionarios!$F12 -> 0 | F12: =Funcionarios!$E12 -> 0 | G12: =MAX(C12+D12+E12-F12,0) -> 1392.4687
A13: =Funcionarios!A13 -> Cintia Raquel Da Silva | B13: =Funcionarios!B13 -> cozinha | C13: =(IF(AND(Funcionarios!D13>=1,COUNTIF(Funcionarios!$D$2:$D$191,">=1")>0),(Editavel!$B$17-SUM(Departamentos!$B:$B)-SUM(Funcionarios!$F$2:$F$191))*Editavel!$C$25/COUNTIF(Funcionarios!$D$2:$D$191,">=1"),0)+IF(AND(Funcionarios!D13>=2,COUNTIF(Funcionarios!$D$2:$D$191,">=2")>0),(Editavel!$B$17-SUM(Departamentos!$B:$B)-SUM(Funcionarios!$F$2:$F$191))*Editavel!$C$26/COUNTIF(Funcionarios!$D$2:$D$191,">=2"),0)+IF(AND(Funcionarios!D13>=3,COUNTIF(Funcionarios!$D$2:$D$191,">=3")>0),(Editavel!$B$17-SUM(Departamentos!$B:$B)-SUM(Funcionarios!$F$2:$F$191))*Editavel!$C$27/COUNTIF(Funcionarios!$D$2:$D$191,">=3"),0)+IF(AND(Funcionarios!D13>=4,COUNTIF(Funcionarios!$D$2:$D$191,">=4")>0),(Editavel!$B$17-SUM(Departamentos!$B:$B)-SUM(Funcionarios!$F$2:$F$191))*Editavel!$C$28/COUNTIF(Funcionarios!$D$2:$D$191,">=4"),0)+IF(AND(Funcionarios!D13>=5,COUNTIF(Funcionarios!$D$2:$D$191,">=5")>0),(Editavel!$B$17-SUM(Departamentos!$B:$B)-SUM(Funcionarios!$F$2:$F$191))*Editavel!$C$29/COUNTIF(Funcionarios!$D$2:$D$191,">=5"),0))*IF(Funcionarios!G13>0,Funcionarios!G13/30,1) -> 902.21077 | D13: =IF(COUNTIF(Funcionarios!$B$2:$B$191,Funcionarios!B13)>0,SUMIFS(Departamentos!$B:$B,Departamentos!$C:$C,Funcionarios!B13)/COUNTIF(Funcionarios!$B$2:$B$191,Funcionarios!B13)*IF(Funcionarios!G13>0,Funcionarios!G13/30,1),0) -> 0 | E13: =Funcionarios!$F13 -> 0 | F13: =Funcionarios!$E13 -> 0 | G13: =MAX(C13+D13+E13-F13,0) -> 902.21077
A14: =Funcionarios!A14 -> Clebio Alves de Moura | B14: =Funcionarios!B14 -> serviço | C14: =(IF(AND(Funcionarios!D14>=1,COUNTIF(Funcionarios!$D$2:$D$191,">=1")>0),(Editavel!$B$17-SUM(Departamentos!$B:$B)-SUM(Funcionarios!$F$2:$F$191))*Editavel!$C$25/COUNTIF(Funcionarios!$D$2:$D$191,">=1"),0)+IF(AND(Funcionarios!D14>=2,COUNTIF(Funcionarios!$D$2:$D$191,">=2")>0),(Editavel!$B$17-SUM(Departamentos!$B:$B)-SUM(Funcionarios!$F$2:$F$191))*Editavel!$C$26/COUNTIF(Funcionarios!$D$2:$D$191,">=2"),0)+IF(AND(Funcionarios!D14>=3,COUNTIF(Funcionarios!$D$2:$D$191,">=3")>0),(Editavel!$B$17-SUM(Departamentos!$B:$B)-SUM(Funcionarios!$F$2:$F$191))*Editavel!$C$27/COUNTIF(Funcionarios!$D$2:$D$191,">=3"),0)+IF(AND(Funcionarios!D14>=4,COUNTIF(Funcionarios!$D$2:$D$191,">=4")>0),(Editavel!$B$17-SUM(Departamentos!$B:$B)-SUM(Funcionarios!$F$2:$F$191))*Editavel!$C$28/COUNTIF(Funcionarios!$D$2:$D$191,">=4"),0)+IF(AND(Funcionarios!D14>=5,COUNTIF(Funcionarios!$D$2:$D$191,">=5")>0),(Editavel!$B$17-SUM(Departamentos!$B:$B)-SUM(Funcionarios!$F$2:$F$191))*Editavel!$C$29/COUNTIF(Funcionarios!$D$2:$D$191,">=5"),0))*IF(Funcionarios!G14>0,Funcionarios!G14/30,1) -> 217.89241 | D14: =IF(COUNTIF(Funcionarios!$B$2:$B$191,Funcionarios!B14)>0,SUMIFS(Departamentos!$B:$B,Departamentos!$C:$C,Funcionarios!B14)/COUNTIF(Funcionarios!$B$2:$B$191,Funcionarios!B14)*IF(Funcionarios!G14>0,Funcionarios!G14/30,1),0) -> 0 | E14: =Funcionarios!$F14 -> 0 | F14: =Funcionarios!$E14 -> 0 | G14: =MAX(C14+D14+E14-F14,0) -> 217.89241
A15: =Funcionarios!A15 -> Daniel Luiz De Lima | B15: =Funcionarios!B15 -> manutenção | C15: =(IF(AND(Funcionarios!D15>=1,COUNTIF(Funcionarios!$D$2:$D$191,">=1")>0),(Editavel!$B$17-SUM(Departamentos!$B:$B)-SUM(Funcionarios!$F$2:$F$191))*Editavel!$C$25/COUNTIF(Funcionarios!$D$2:$D$191,">=1"),0)+IF(AND(Funcionarios!D15>=2,COUNTIF(Funcionarios!$D$2:$D$191,">=2")>0),(Editavel!$B$17-SUM(Departamentos!$B:$B)-SUM(Funcionarios!$F$2:$F$191))*Editavel!$C$26/COUNTIF(Funcionarios!$D$2:$D$191,">=2"),0)+IF(AND(Funcionarios!D15>=3,COUNTIF(Funcionarios!$D$2:$D$191,">=3")>0),(Editavel!$B$17-SUM(Departamentos!$B:$B)-SUM(Funcionarios!$F$2:$F$191))*Editavel!$C$27/COUNTIF(Funcionarios!$D$2:$D$191,">=3"),0)+IF(AND(Funcionarios!D15>=4,COUNTIF(Funcionarios!$D$2:$D$191,">=4")>0),(Editavel!$B$17-SUM(Departamentos!$B:$B)-SUM(Funcionarios!$F$2:$F$191))*Editavel!$C$28/COUNTIF(Funcionarios!$D$2:$D$191,">=4"),0)+IF(AND(Funcionarios!D15>=5,COUNTIF(Funcionarios!$D$2:$D$191,">=5")>0),(Editavel!$B$17-SUM(Departamentos!$B:$B)-SUM(Funcionarios!$F$2:$F$191))*Editavel!$C$29/COUNTIF(Funcionarios!$D$2:$D$191,">=5"),0))*IF(Funcionarios!G15>0,Funcionarios!G15/30,1) -> 217.89241 | D15: =IF(COUNTIF(Funcionarios!$B$2:$B$191,Funcionarios!B15)>0,SUMIFS(Departamentos!$B:$B,Departamentos!$C:$C,Funcionarios!B15)/COUNTIF(Funcionarios!$B$2:$B$191,Funcionarios!B15)*IF(Funcionarios!G15>0,Funcionarios!G15/30,1),0) -> 0 | E15: =Funcionarios!$F15 -> 0 | F15: =Funcionarios!$E15 -> 0 | G15: =MAX(C15+D15+E15-F15,0) -> 217.89241
A16: =Funcionarios!A16 -> Danilo Cesar Silva Lima | B16: =Funcionarios!B16 -> serviço | C16: =(IF(AND(Funcionarios!D16>=1,COUNTIF(Funcionarios!$D$2:$D$191,">=1")>0),(Editavel!$B$17-SUM(Departamentos!$B:$B)-SUM(Funcionarios!$F$2:$F$191))*Editavel!$C$25/COUNTIF(Funcionarios!$D$2:$D$191,">=1"),0)+IF(AND(Funcionarios!D16>=2,COUNTIF(Funcionarios!$D$2:$D$191,">=2")>0),(Editavel!$B$17-SUM(Departamentos!$B:$B)-SUM(Funcionarios!$F$2:$F$191))*Editavel!$C$26/COUNTIF(Funcionarios!$D$2:$D$191,">=2"),0)+IF(AND(Funcionarios!D16>=3,COUNTIF(Funcionarios!$D$2:$D$191,">=3")>0),(Editavel!$B$17-SUM(Departamentos!$B:$B)-SUM(Funcionarios!$F$2:$F$191))*Editavel!$C$27/COUNTIF(Funcionarios!$D$2:$D$191,">=3"),0)+IF(AND(Funcionarios!D16>=4,COUNTIF(Funcionarios!$D$2:$D$191,">=4")>0),(Editavel!$B$17-SUM(Departamentos!$B:$B)-SUM(Funcionarios!$F$2:$F$191))*Editavel!$C$28/COUNTIF(Funcionarios!$D$2:$D$191,">=4"),0)+IF(AND(Funcionarios!D16>=5,COUNTIF(Funcionarios!$D$2:$D$191,">=5")>0),(Editavel!$B$17-SUM(Departamentos!$B:$B)-SUM(Funcionarios!$F$2:$F$191))*Editavel!$C$29/COUNTIF(Funcionarios!$D$2:$D$191,">=5"),0))*IF(Funcionarios!G16>0,Funcionarios!G16/30,1) -> 554.94474 | D16: =IF(COUNTIF(Funcionarios!$B$2:$B$191,Funcionarios!B16)>0,SUMIFS(Departamentos!$B:$B,Departamentos!$C:$C,Funcionarios!B16)/COUNTIF(Funcionarios!$B$2:$B$191,Funcionarios!B16)*IF(Funcionarios!G16>0,Funcionarios!G16/30,1),0) -> 0 | E16: =Funcionarios!$F16 -> 0 | F16: =Funcionarios!$E16 -> 0 | G16: =MAX(C16+D16+E16-F16,0) -> 554.94474
A17: =Funcionarios!A17 -> Dina Priscila dos Santos Nunes | B17: =Funcionarios!B17 -> governança | C17: =(IF(AND(Funcionarios!D17>=1,COUNTIF(Funcionarios!$D$2:$D$191,">=1")>0),(Editavel!$B$17-SUM(Departamentos!$B:$B)-SUM(Funcionarios!$F$2:$F$191))*Editavel!$C$25/COUNTIF(Funcionarios!$D$2:$D$191,">=1"),0)+IF(AND(Funcionarios!D17>=2,COUNTIF(Funcionarios!$D$2:$D$191,">=2")>0),(Editavel!$B$17-SUM(Departamentos!$B:$B)-SUM(Funcionarios!$F$2:$F$191))*Editavel!$C$26/COUNTIF(Funcionarios!$D$2:$D$191,">=2"),0)+IF(AND(Funcionarios!D17>=3,COUNTIF(Funcionarios!$D$2:$D$191,">=3")>0),(Editavel!$B$17-SUM(Departamentos!$B:$B)-SUM(Funcionarios!$F$2:$F$191))*Editavel!$C$27/COUNTIF(Funcionarios!$D$2:$D$191,">=3"),0)+IF(AND(Funcionarios!D17>=4,COUNTIF(Funcionarios!$D$2:$D$191,">=4")>0),(Editavel!$B$17-SUM(Departamentos!$B:$B)-SUM(Funcionarios!$F$2:$F$191))*Editavel!$C$28/COUNTIF(Funcionarios!$D$2:$D$191,">=4"),0)+IF(AND(Funcionarios!D17>=5,COUNTIF(Funcionarios!$D$2:$D$191,">=5")>0),(Editavel!$B$17-SUM(Departamentos!$B:$B)-SUM(Funcionarios!$F$2:$F$191))*Editavel!$C$29/COUNTIF(Funcionarios!$D$2:$D$191,">=5"),0))*IF(Funcionarios!G17>0,Funcionarios!G17/30,1) -> 554.94474 | D17: =IF(COUNTIF(Funcionarios!$B$2:$B$191,Funcionarios!B17)>0,SUMIFS(Departamentos!$B:$B,Departamentos!$C:$C,Funcionarios!B17)/COUNTIF(Funcionarios!$B$2:$B$191,Funcionarios!B17)*IF(Funcionarios!G17>0,Funcionarios!G17/30,1),0) -> 0 | E17: =Funcionarios!$F17 -> 0 | F17: =Funcionarios!$E17 -> 0 | G17: =MAX(C17+D17+E17-F17,0) -> 554.94474
A18: =Funcionarios!A18 -> Elenilda Dos Santos Da Silva | B18: =Funcionarios!B18 -> cozinha | C18: =(IF(AND(Funcionarios!D18>=1,COUNTIF(Funcionarios!$D$2:$D$191,">=1")>0),(Editavel!$B$17-SUM(Departamentos!$B:$B)-SUM(Funcionarios!$F$2:$F$191))*Editavel!$C$25/COUNTIF(Funcionarios!$D$2:$D$191,">=1"),0)+IF(AND(Funcionarios!D18>=2,COUNTIF(Funcionarios!$D$2:$D$191,">=2")>0),(Editavel!$B$17-SUM(Departamentos!$B:$B)-SUM(Funcionarios!$F$2:$F$191))*Editavel!$C$26/COUNTIF(Funcionarios!$D$2:$D$191,">=2"),0)+IF(AND(Funcionarios!D18>=3,COUNTIF(Funcionarios!$D$2:$D$191,">=3")>0),(Editavel!$B$17-SUM(Departamentos!$B:$B)-SUM(Funcionarios!$F$2:$F$191))*Editavel!$C$27/COUNTIF(Funcionarios!$D$2:$D$191,">=3"),0)+IF(AND(Funcionarios!D18>=4,COUNTIF(Funcionarios!$D$2:$D$191,">=4")>0),(Editavel!$B$17-SUM(Departamentos!$B:$B)-SUM(Funcionarios!$F$2:$F$191))*Editavel!$C$28/COUNTIF(Funcionarios!$D$2:$D$191,">=4"),0)+IF(AND(Funcionarios!D18>=5,COUNTIF(Funcionarios!$D$2:$D$191,">=5")>0),(Editavel!$B$17-SUM(Departamentos!$B:$B)-SUM(Funcionarios!$F$2:$F$191))*Editavel!$C$29/COUNTIF(Funcionarios!$D$2:$D$191,">=5"),0))*IF(Funcionarios!G18>0,Funcionarios!G18/30,1) -> 217.89241 | D18: =IF(COUNTIF(Funcionarios!$B$2:$B$191,Funcionarios!B18)>0,SUMIFS(Departamentos!$B:$B,Departamentos!$C:$C,Funcionarios!B18)/COUNTIF(Funcionarios!$B$2:$B$191,Funcionarios!B18)*IF(Funcionarios!G18>0,Funcionarios!G18/30,1),0) -> 0 | E18: =Funcionarios!$F18 -> 0 | F18: =Funcionarios!$E18 -> 0 | G18: =MAX(C18+D18+E18-F18,0) -> 217.89241
A19: =Funcionarios!A19 -> Eliete Maria Dos Santos Da Silva | B19: =Funcionarios!B19 -> cozinha | C19: =(IF(AND(Funcionarios!D19>=1,COUNTIF(Funcionarios!$D$2:$D$191,">=1")>0),(Editavel!$B$17-SUM(Departamentos!$B:$B)-SUM(Funcionarios!$F$2:$F$191))*Editavel!$C$25/COUNTIF(Funcionarios!$D$2:$D$191,">=1"),0)+IF(AND(Funcionarios!D19>=2,COUNTIF(Funcionarios!$D$2:$D$191,">=2")>0),(Editavel!$B$17-SUM(Departamentos!$B:$B)-SUM(Funcionarios!$F$2:$F$191))*Editavel!$C$26/COUNTIF(Funcionarios!$D$2:$D$191,">=2"),0)+IF(AND(Funcionarios!D19>=3,COUNTIF(Funcionarios!$D$2:$D$191,">=3")>0),(Editavel!$B$17-SUM(Departamentos!$B:$B)-SUM(Funcionarios!$F$2:$F$191))*Editavel!$C$27/COUNTIF(Funcionarios!$D$2:$D$191,">=3"),0)+IF(AND(Funcionarios!D19>=4,COUNTIF(Funcionarios!$D$2:$D$191,">=4")>0),(Editavel!$B$17-SUM(Departamentos!$B:$B)-SUM(Funcionarios!$F$2:$F$191))*Editavel!$C$28/COUNTIF(Funcionarios!$D$2:$D$191,">=4"),0)+IF(AND(Funcionarios!D19>=5,COUNTIF(Funcionarios!$D$2:$D$191,">=5")>0),(Editavel!$B$17-SUM(Departamentos!$B:$B)-SUM(Funcionarios!$F$2:$F$191))*Editavel!$C$29/COUNTIF(Funcionarios!$D$2:$D$191,">=5"),0))*IF(Funcionarios!G19>0,Funcionarios!G19/30,1) -> 116.20929 | D19: =IF(COUNTIF(Funcionarios!$B$2:$B$191,Funcionarios!B19)>0,SUMIFS(Departamentos!$B:$B,Departamentos!$C:$C,Funcionarios!B19)/COUNTIF(Funcionarios!$B$2:$B$191,Funcionarios!B19)*IF(Funcionarios!G19>0,Funcionarios!G19/30,1),0) -> 0 | E19: =Funcionarios!$F19 -> 0 | F19: =Funcionarios!$E19 -> 0 | G19: =MAX(C19+D19+E19-F19,0) -> 116.20929
A20: =Funcionarios!A20 -> Erick Manoel Santos Do Nascimento | B20: =Funcionarios!B20 -> serviço | C20: =(IF(AND(Funcionarios!D20>=1,COUNTIF(Funcionarios!$D$2:$D$191,">=1")>0),(Editavel!$B$17-SUM(Departamentos!$B:$B)-SUM(Funcionarios!$F$2:$F$191))*Editavel!$C$25/COUNTIF(Funcionarios!$D$2:$D$191,">=1"),0)+IF(AND(Funcionarios!D20>=2,COUNTIF(Funcionarios!$D$2:$D$191,">=2")>0),(Editavel!$B$17-SUM(Departamentos!$B:$B)-SUM(Funcionarios!$F$2:$F$191))*Editavel!$C$26/COUNTIF(Funcionarios!$D$2:$D$191,">=2"),0)+IF(AND(Funcionarios!D20>=3,COUNTIF(Funcionarios!$D$2:$D$191,">=3")>0),(Editavel!$B$17-SUM(Departamentos!$B:$B)-SUM(Funcionarios!$F$2:$F$191))*Editavel!$C$27/COUNTIF(Funcionarios!$D$2:$D$191,">=3"),0)+IF(AND(Funcionarios!D20>=4,COUNTIF(Funcionarios!$D$2:$D$191,">=4")>0),(Editavel!$B$17-SUM(Departamentos!$B:$B)-SUM(Funcionarios!$F$2:$F$191))*Editavel!$C$28/COUNTIF(Funcionarios!$D$2:$D$191,">=4"),0)+IF(AND(Funcionarios!D20>=5,COUNTIF(Funcionarios!$D$2:$D$191,">=5")>0),(Editavel!$B$17-SUM(Departamentos!$B:$B)-SUM(Funcionarios!$F$2:$F$191))*Editavel!$C$29/COUNTIF(Funcionarios!$D$2:$D$191,">=5"),0))*IF(Funcionarios!G20>0,Funcionarios!G20/30,1) -> 72.630804 | D20: =IF(COUNTIF(Funcionarios!$B$2:$B$191,Funcionarios!B20)>0,SUMIFS(Departamentos!$B:$B,Departamentos!$C:$C,Funcionarios!B20)/COUNTIF(Funcionarios!$B$2:$B$191,Funcionarios!B20)*IF(Funcionarios!G20>0,Funcionarios!G20/30,1),0) -> 0 | E20: =Funcionarios!$F20 -> 0 | F20: =Funcionarios!$E20 -> 0 | G20: =MAX(C20+D20+E20-F20,0) -> 72.630804
... A56: =Funcionarios!A56 -> 0 | B56: =Funcionarios!B56 -> 0 | C56: =(IF(AND(Funcionarios!D56>=1,COUNTIF(Funcionarios!$D$2:$D$191,">=1")>0),(Editavel!$B$17-SUM(Departamentos!$B:$B)-SUM(Funcionarios!$F$2:$F$191))*Editavel!$C$25/COUNTIF(Funcionarios!$D$2:$D$191,">=1"),0)+IF(AND(Funcionarios!D56>=2,COUNTIF(Funcionarios!$D$2:$D$191,">=2")>0),(Editavel!$B$17-SUM(Departamentos!$B:$B)-SUM(Funcionarios!$F$2:$F$191))*Editavel!$C$26/COUNTIF(Funcionarios!$D$2:$D$191,">=2"),0)+IF(AND(Funcionarios!D56>=3,COUNTIF(Funcionarios!$D$2:$D$191,">=3")>0),(Editavel!$B$17-SUM(Departamentos!$B:$B)-SUM(Funcionarios!$F$2:$F$191))*Editavel!$C$27/COUNTIF(Funcionarios!$D$2:$D$191,">=3"),0)+IF(AND(Funcionarios!D56>=4,COUNTIF(Funcionarios!$D$2:$D$191,">=4")>0),(Editavel!$B$17-SUM(Departamentos!$B:$B)-SUM(Funcionarios!$F$2:$F$191))*Editavel!$C$28/COUNTIF(Funcionarios!$D$2:$D$191,">=4"),0)+IF(AND(Funcionarios!D56>=5,COUNTIF(Funcionarios!$D$2:$D$191,">=5")>0),(Editavel!$B$17-SUM(Departamentos!$B:$B)-SUM(Funcionarios!$F$2:$F$191))*Editavel!$C$29/COUNTIF(Funcionarios!$D$2:$D$191,">=5"),0))*IF(Funcionarios!G56>0,Funcionarios!G56/30,1) -> 0 | D56: =IF(COUNTIF(Funcionarios!$B$2:$B$191,Funcionarios!B56)>0,SUMIFS(Departamentos!$B:$B,Departamentos!$C:$C,Funcionarios!B56)/COUNTIF(Funcionarios!$B$2:$B$191,Funcionarios!B56)*IF(Funcionarios!G56>0,Funcionarios!G56/30,1),0) -> 0 | E56: =Funcionarios!$F56 -> 0 | F56: =Funcionarios!$E56 -> 0 | G56: =MAX(C56+D56+E56-F56,0) -> 0
A57: =Funcionarios!A47 -> 0 | B57: =Funcionarios!B47 -> 0 | C57: =(IF(AND(Funcionarios!D47>=1,COUNTIF(Funcionarios!$D$2:$D$191,">=1")>0),(Editavel!$B$17-SUM(Departamentos!$B:$B)-SUM(Funcionarios!$F$2:$F$191))*Editavel!$C$25/COUNTIF(Funcionarios!$D$2:$D$191,">=1"),0)+IF(AND(Funcionarios!D47>=2,COUNTIF(Funcionarios!$D$2:$D$191,">=2")>0),(Editavel!$B$17-SUM(Departamentos!$B:$B)-SUM(Funcionarios!$F$2:$F$191))*Editavel!$C$26/COUNTIF(Funcionarios!$D$2:$D$191,">=2"),0)+IF(AND(Funcionarios!D47>=3,COUNTIF(Funcionarios!$D$2:$D$191,">=3")>0),(Editavel!$B$17-SUM(Departamentos!$B:$B)-SUM(Funcionarios!$F$2:$F$191))*Editavel!$C$27/COUNTIF(Funcionarios!$D$2:$D$191,">=3"),0)+IF(AND(Funcionarios!D47>=4,COUNTIF(Funcionarios!$D$2:$D$191,">=4")>0),(Editavel!$B$17-SUM(Departamentos!$B:$B)-SUM(Funcionarios!$F$2:$F$191))*Editavel!$C$28/COUNTIF(Funcionarios!$D$2:$D$191,">=4"),0)+IF(AND(Funcionarios!D47>=5,COUNTIF(Funcionarios!$D$2:$D$191,">=5")>0),(Editavel!$B$17-SUM(Departamentos!$B:$B)-SUM(Funcionarios!$F$2:$F$191))*Editavel!$C$29/COUNTIF(Funcionarios!$D$2:$D$191,">=5"),0))*IF(Funcionarios!G47>0,Funcionarios!G47/30,1) -> 0 | D57: =IF(COUNTIF(Funcionarios!$B$2:$B$191,Funcionarios!B47)>0,SUMIFS(Departamentos!$B:$B,Departamentos!$C:$C,Funcionarios!B47)/COUNTIF(Funcionarios!$B$2:$B$191,Funcionarios!B47)*IF(Funcionarios!G47>0,Funcionarios!G47/30,1),0) -> 0 | E57: =Funcionarios!$F47 -> 0 | F57: =Funcionarios!$E47 -> 0 | G57: =MAX(C57+D57+E57-F57,0) -> 0
A58: =Funcionarios!A48 -> 0 | B58: =Funcionarios!B48 -> 0 | C58: =(IF(AND(Funcionarios!D48>=1,COUNTIF(Funcionarios!$D$2:$D$191,">=1")>0),(Editavel!$B$17-SUM(Departamentos!$B:$B)-SUM(Funcionarios!$F$2:$F$191))*Editavel!$C$25/COUNTIF(Funcionarios!$D$2:$D$191,">=1"),0)+IF(AND(Funcionarios!D48>=2,COUNTIF(Funcionarios!$D$2:$D$191,">=2")>0),(Editavel!$B$17-SUM(Departamentos!$B:$B)-SUM(Funcionarios!$F$2:$F$191))*Editavel!$C$26/COUNTIF(Funcionarios!$D$2:$D$191,">=2"),0)+IF(AND(Funcionarios!D48>=3,COUNTIF(Funcionarios!$D$2:$D$191,">=3")>0),(Editavel!$B$17-SUM(Departamentos!$B:$B)-SUM(Funcionarios!$F$2:$F$191))*Editavel!$C$27/COUNTIF(Funcionarios!$D$2:$D$191,">=3"),0)+IF(AND(Funcionarios!D48>=4,COUNTIF(Funcionarios!$D$2:$D$191,">=4")>0),(Editavel!$B$17-SUM(Departamentos!$B:$B)-SUM(Funcionarios!$F$2:$F$191))*Editavel!$C$28/COUNTIF(Funcionarios!$D$2:$D$191,">=4"),0)+IF(AND(Funcionarios!D48>=5,COUNTIF(Funcionarios!$D$2:$D$191,">=5")>0),(Editavel!$B$17-SUM(Departamentos!$B:$B)-SUM(Funcionarios!$F$2:$F$191))*Editavel!$C$29/COUNTIF(Funcionarios!$D$2:$D$191,">=5"),0))*IF(Funcionarios!G48>0,Funcionarios!G48/30,1) -> 0 | D58: =IF(COUNTIF(Funcionarios!$B$2:$B$191,Funcionarios!B48)>0,SUMIFS(Departamentos!$B:$B,Departamentos!$C:$C,Funcionarios!B48)/COUNTIF(Funcionarios!$B$2:$B$191,Funcionarios!B48)*IF(Funcionarios!G48>0,Funcionarios!G48/30,1),0) -> 0 | E58: =Funcionarios!$F48 -> 0 | F58: =Funcionarios!$E48 -> 0 | G58: =MAX(C58+D58+E58-F58,0) -> 0
A59: =Funcionarios!A49 -> 0 | B59: =Funcionarios!B49 -> 0 | C59: =(IF(AND(Funcionarios!D49>=1,COUNTIF(Funcionarios!$D$2:$D$191,">=1")>0),(Editavel!$B$17-SUM(Departamentos!$B:$B)-SUM(Funcionarios!$F$2:$F$191))*Editavel!$C$25/COUNTIF(Funcionarios!$D$2:$D$191,">=1"),0)+IF(AND(Funcionarios!D49>=2,COUNTIF(Funcionarios!$D$2:$D$191,">=2")>0),(Editavel!$B$17-SUM(Departamentos!$B:$B)-SUM(Funcionarios!$F$2:$F$191))*Editavel!$C$26/COUNTIF(Funcionarios!$D$2:$D$191,">=2"),0)+IF(AND(Funcionarios!D49>=3,COUNTIF(Funcionarios!$D$2:$D$191,">=3")>0),(Editavel!$B$17-SUM(Departamentos!$B:$B)-SUM(Funcionarios!$F$2:$F$191))*Editavel!$C$27/COUNTIF(Funcionarios!$D$2:$D$191,">=3"),0)+IF(AND(Funcionarios!D49>=4,COUNTIF(Funcionarios!$D$2:$D$191,">=4")>0),(Editavel!$B$17-SUM(Departamentos!$B:$B)-SUM(Funcionarios!$F$2:$F$191))*Editavel!$C$28/COUNTIF(Funcionarios!$D$2:$D$191,">=4"),0)+IF(AND(Funcionarios!D49>=5,COUNTIF(Funcionarios!$D$2:$D$191,">=5")>0),(Editavel!$B$17-SUM(Departamentos!$B:$B)-SUM(Funcionarios!$F$2:$F$191))*Editavel!$C$29/COUNTIF(Funcionarios!$D$2:$D$191,">=5"),0))*IF(Funcionarios!G49>0,Funcionarios!G49/30,1) -> 0 | D59: =IF(COUNTIF(Funcionarios!$B$2:$B$191,Funcionarios!B49)>0,SUMIFS(Departamentos!$B:$B,Departamentos!$C:$C,Funcionarios!B49)/COUNTIF(Funcionarios!$B$2:$B$191,Funcionarios!B49)*IF(Funcionarios!G49>0,Funcionarios!G49/30,1),0) -> 0 | E59: =Funcionarios!$F49 -> 0 | F59: =Funcionarios!$E49 -> 0 | G59: =MAX(C59+D59+E59-F59,0) -> 0
A60: =Funcionarios!A50 -> 0 | B60: =Funcionarios!B50 -> 0 | C60: =(IF(AND(Funcionarios!D50>=1,COUNTIF(Funcionarios!$D$2:$D$191,">=1")>0),(Editavel!$B$17-SUM(Departamentos!$B:$B)-SUM(Funcionarios!$F$2:$F$191))*Editavel!$C$25/COUNTIF(Funcionarios!$D$2:$D$191,">=1"),0)+IF(AND(Funcionarios!D50>=2,COUNTIF(Funcionarios!$D$2:$D$191,">=2")>0),(Editavel!$B$17-SUM(Departamentos!$B:$B)-SUM(Funcionarios!$F$2:$F$191))*Editavel!$C$26/COUNTIF(Funcionarios!$D$2:$D$191,">=2"),0)+IF(AND(Funcionarios!D50>=3,COUNTIF(Funcionarios!$D$2:$D$191,">=3")>0),(Editavel!$B$17-SUM(Departamentos!$B:$B)-SUM(Funcionarios!$F$2:$F$191))*Editavel!$C$27/COUNTIF(Funcionarios!$D$2:$D$191,">=3"),0)+IF(AND(Funcionarios!D50>=4,COUNTIF(Funcionarios!$D$2:$D$191,">=4")>0),(Editavel!$B$17-SUM(Departamentos!$B:$B)-SUM(Funcionarios!$F$2:$F$191))*Editavel!$C$28/COUNTIF(Funcionarios!$D$2:$D$191,">=4"),0)+IF(AND(Funcionarios!D50>=5,COUNTIF(Funcionarios!$D$2:$D$191,">=5")>0),(Editavel!$B$17-SUM(Departamentos!$B:$B)-SUM(Funcionarios!$F$2:$F$191))*Editavel!$C$29/COUNTIF(Funcionarios!$D$2:$D$191,">=5"),0))*IF(Funcionarios!G50>0,Funcionarios!G50/30,1) -> 0 | D60: =IF(COUNTIF(Funcionarios!$B$2:$B$191,Funcionarios!B50)>0,SUMIFS(Departamentos!$B:$B,Departamentos!$C:$C,Funcionarios!B50)/COUNTIF(Funcionarios!$B$2:$B$191,Funcionarios!B50)*IF(Funcionarios!G50>0,Funcionarios!G50/30,1),0) -> 0 | E60: =Funcionarios!$F50 -> 0 | F60: =Funcionarios!$E50 -> 0 | G60: =MAX(C60+D60+E60-F60,0) -> 0
A61: =Funcionarios!A51 -> 0 | B61: =Funcionarios!B51 -> 0 | C61: =(IF(AND(Funcionarios!D51>=1,COUNTIF(Funcionarios!$D$2:$D$191,">=1")>0),(Editavel!$B$17-SUM(Departamentos!$B:$B)-SUM(Funcionarios!$F$2:$F$191))*Editavel!$C$25/COUNTIF(Funcionarios!$D$2:$D$191,">=1"),0)+IF(AND(Funcionarios!D51>=2,COUNTIF(Funcionarios!$D$2:$D$191,">=2")>0),(Editavel!$B$17-SUM(Departamentos!$B:$B)-SUM(Funcionarios!$F$2:$F$191))*Editavel!$C$26/COUNTIF(Funcionarios!$D$2:$D$191,">=2"),0)+IF(AND(Funcionarios!D51>=3,COUNTIF(Funcionarios!$D$2:$D$191,">=3")>0),(Editavel!$B$17-SUM(Departamentos!$B:$B)-SUM(Funcionarios!$F$2:$F$191))*Editavel!$C$27/COUNTIF(Funcionarios!$D$2:$D$191,">=3"),0)+IF(AND(Funcionarios!D51>=4,COUNTIF(Funcionarios!$D$2:$D$191,">=4")>0),(Editavel!$B$17-SUM(Departamentos!$B:$B)-SUM(Funcionarios!$F$2:$F$191))*Editavel!$C$28/COUNTIF(Funcionarios!$D$2:$D$191,">=4"),0)+IF(AND(Funcionarios!D51>=5,COUNTIF(Funcionarios!$D$2:$D$191,">=5")>0),(Editavel!$B$17-SUM(Departamentos!$B:$B)-SUM(Funcionarios!$F$2:$F$191))*Editavel!$C$29/COUNTIF(Funcionarios!$D$2:$D$191,">=5"),0))*IF(Funcionarios!G51>0,Funcionarios!G51/30,1) -> 0 | D61: =IF(COUNTIF(Funcionarios!$B$2:$B$191,Funcionarios!B51)>0,SUMIFS(Departamentos!$B:$B,Departamentos!$C:$C,Funcionarios!B51)/COUNTIF(Funcionarios!$B$2:$B$191,Funcionarios!B51)*IF(Funcionarios!G51>0,Funcionarios!G51/30,1),0) -> 0 | E61: =Funcionarios!$F51 -> 0 | F61: =Funcionarios!$E51 -> 0 | G61: =MAX(C61+D61+E61-F61,0) -> 0
A62: =Funcionarios!A52 -> 0 | B62: =Funcionarios!B52 -> 0 | C62: =(IF(AND(Funcionarios!D52>=1,COUNTIF(Funcionarios!$D$2:$D$191,">=1")>0),(Editavel!$B$17-SUM(Departamentos!$B:$B)-SUM(Funcionarios!$F$2:$F$191))*Editavel!$C$25/COUNTIF(Funcionarios!$D$2:$D$191,">=1"),0)+IF(AND(Funcionarios!D52>=2,COUNTIF(Funcionarios!$D$2:$D$191,">=2")>0),(Editavel!$B$17-SUM(Departamentos!$B:$B)-SUM(Funcionarios!$F$2:$F$191))*Editavel!$C$26/COUNTIF(Funcionarios!$D$2:$D$191,">=2"),0)+IF(AND(Funcionarios!D52>=3,COUNTIF(Funcionarios!$D$2:$D$191,">=3")>0),(Editavel!$B$17-SUM(Departamentos!$B:$B)-SUM(Funcionarios!$F$2:$F$191))*Editavel!$C$27/COUNTIF(Funcionarios!$D$2:$D$191,">=3"),0)+IF(AND(Funcionarios!D52>=4,COUNTIF(Funcionarios!$D$2:$D$191,">=4")>0),(Editavel!$B$17-SUM(Departamentos!$B:$B)-SUM(Funcionarios!$F$2:$F$191))*Editavel!$C$28/COUNTIF(Funcionarios!$D$2:$D$191,">=4"),0)+IF(AND(Funcionarios!D52>=5,COUNTIF(Funcionarios!$D$2:$D$191,">=5")>0),(Editavel!$B$17-SUM(Departamentos!$B:$B)-SUM(Funcionarios!$F$2:$F$191))*Editavel!$C$29/COUNTIF(Funcionarios!$D$2:$D$191,">=5"),0))*IF(Funcionarios!G52>0,Funcionarios!G52/30,1) -> 0 | D62: =IF(COUNTIF(Funcionarios!$B$2:$B$191,Funcionarios!B52)>0,SUMIFS(Departamentos!$B:$B,Departamentos!$C:$C,Funcionarios!B52)/COUNTIF(Funcionarios!$B$2:$B$191,Funcionarios!B52)*IF(Funcionarios!G52>0,Funcionarios!G52/30,1),0) -> 0 | E62: =Funcionarios!$F52 -> 0 | F62: =Funcionarios!$E52 -> 0 | G62: =MAX(C62+D62+E62-F62,0) -> 0
A63: =Funcionarios!A53 -> 0 | B63: =Funcionarios!B53 -> 0 | C63: =(IF(AND(Funcionarios!D53>=1,COUNTIF(Funcionarios!$D$2:$D$191,">=1")>0),(Editavel!$B$17-SUM(Departamentos!$B:$B)-SUM(Funcionarios!$F$2:$F$191))*Editavel!$C$25/COUNTIF(Funcionarios!$D$2:$D$191,">=1"),0)+IF(AND(Funcionarios!D53>=2,COUNTIF(Funcionarios!$D$2:$D$191,">=2")>0),(Editavel!$B$17-SUM(Departamentos!$B:$B)-SUM(Funcionarios!$F$2:$F$191))*Editavel!$C$26/COUNTIF(Funcionarios!$D$2:$D$191,">=2"),0)+IF(AND(Funcionarios!D53>=3,COUNTIF(Funcionarios!$D$2:$D$191,">=3")>0),(Editavel!$B$17-SUM(Departamentos!$B:$B)-SUM(Funcionarios!$F$2:$F$191))*Editavel!$C$27/COUNTIF(Funcionarios!$D$2:$D$191,">=3"),0)+IF(AND(Funcionarios!D53>=4,COUNTIF(Funcionarios!$D$2:$D$191,">=4")>0),(Editavel!$B$17-SUM(Departamentos!$B:$B)-SUM(Funcionarios!$F$2:$F$191))*Editavel!$C$28/COUNTIF(Funcionarios!$D$2:$D$191,">=4"),0)+IF(AND(Funcionarios!D53>=5,COUNTIF(Funcionarios!$D$2:$D$191,">=5")>0),(Editavel!$B$17-SUM(Departamentos!$B:$B)-SUM(Funcionarios!$F$2:$F$191))*Editavel!$C$29/COUNTIF(Funcionarios!$D$2:$D$191,">=5"),0))*IF(Funcionarios!G53>0,Funcionarios!G53/30,1) -> 0 | D63: =IF(COUNTIF(Funcionarios!$B$2:$B$191,Funcionarios!B53)>0,SUMIFS(Departamentos!$B:$B,Departamentos!$C:$C,Funcionarios!B53)/COUNTIF(Funcionarios!$B$2:$B$191,Funcionarios!B53)*IF(Funcionarios!G53>0,Funcionarios!G53/30,1),0) -> 0 | E63: =Funcionarios!$F53 -> 0 | F63: =Funcionarios!$E53 -> 0 | G63: =MAX(C63+D63+E63-F63,0) -> 0
A64: =Funcionarios!A54 -> 0 | B64: =Funcionarios!B54 -> 0 | C64: =(IF(AND(Funcionarios!D54>=1,COUNTIF(Funcionarios!$D$2:$D$191,">=1")>0),(Editavel!$B$17-SUM(Departamentos!$B:$B)-SUM(Funcionarios!$F$2:$F$191))*Editavel!$C$25/COUNTIF(Funcionarios!$D$2:$D$191,">=1"),0)+IF(AND(Funcionarios!D54>=2,COUNTIF(Funcionarios!$D$2:$D$191,">=2")>0),(Editavel!$B$17-SUM(Departamentos!$B:$B)-SUM(Funcionarios!$F$2:$F$191))*Editavel!$C$26/COUNTIF(Funcionarios!$D$2:$D$191,">=2"),0)+IF(AND(Funcionarios!D54>=3,COUNTIF(Funcionarios!$D$2:$D$191,">=3")>0),(Editavel!$B$17-SUM(Departamentos!$B:$B)-SUM(Funcionarios!$F$2:$F$191))*Editavel!$C$27/COUNTIF(Funcionarios!$D$2:$D$191,">=3"),0)+IF(AND(Funcionarios!D54>=4,COUNTIF(Funcionarios!$D$2:$D$191,">=4")>0),(Editavel!$B$17-SUM(Departamentos!$B:$B)-SUM(Funcionarios!$F$2:$F$191))*Editavel!$C$28/COUNTIF(Funcionarios!$D$2:$D$191,">=4"),0)+IF(AND(Funcionarios!D54>=5,COUNTIF(Funcionarios!$D$2:$D$191,">=5")>0),(Editavel!$B$17-SUM(Departamentos!$B:$B)-SUM(Funcionarios!$F$2:$F$191))*Editavel!$C$29/COUNTIF(Funcionarios!$D$2:$D$191,">=5"),0))*IF(Funcionarios!G54>0,Funcionarios!G54/30,1) -> 0 | D64: =IF(COUNTIF(Funcionarios!$B$2:$B$191,Funcionarios!B54)>0,SUMIFS(Departamentos!$B:$B,Departamentos!$C:$C,Funcionarios!B54)/COUNTIF(Funcionarios!$B$2:$B$191,Funcionarios!B54)*IF(Funcionarios!G54>0,Funcionarios!G54/30,1),0) -> 0 | E64: =Funcionarios!$F54 -> 0 | F64: =Funcionarios!$E54 -> 0 | G64: =MAX(C64+D64+E64-F64,0) -> 0
A65: =Funcionarios!A55 -> 0 | B65: =Funcionarios!B55 -> 0 | C65: =(IF(AND(Funcionarios!D55>=1,COUNTIF(Funcionarios!$D$2:$D$191,">=1")>0),(Editavel!$B$17-SUM(Departamentos!$B:$B)-SUM(Funcionarios!$F$2:$F$191))*Editavel!$C$25/COUNTIF(Funcionarios!$D$2:$D$191,">=1"),0)+IF(AND(Funcionarios!D55>=2,COUNTIF(Funcionarios!$D$2:$D$191,">=2")>0),(Editavel!$B$17-SUM(Departamentos!$B:$B)-SUM(Funcionarios!$F$2:$F$191))*Editavel!$C$26/COUNTIF(Funcionarios!$D$2:$D$191,">=2"),0)+IF(AND(Funcionarios!D55>=3,COUNTIF(Funcionarios!$D$2:$D$191,">=3")>0),(Editavel!$B$17-SUM(Departamentos!$B:$B)-SUM(Funcionarios!$F$2:$F$191))*Editavel!$C$27/COUNTIF(Funcionarios!$D$2:$D$191,">=3"),0)+IF(AND(Funcionarios!D55>=4,COUNTIF(Funcionarios!$D$2:$D$191,">=4")>0),(Editavel!$B$17-SUM(Departamentos!$B:$B)-SUM(Funcionarios!$F$2:$F$191))*Editavel!$C$28/COUNTIF(Funcionarios!$D$2:$D$191,">=4"),0)+IF(AND(Funcionarios!D55>=5,COUNTIF(Funcionarios!$D$2:$D$191,">=5")>0),(Editavel!$B$17-SUM(Departamentos!$B:$B)-SUM(Funcionarios!$F$2:$F$191))*Editavel!$C$29/COUNTIF(Funcionarios!$D$2:$D$191,">=5"),0))*IF(Funcionarios!G55>0,Funcionarios!G55/30,1) -> 0 | D65: =IF(COUNTIF(Funcionarios!$B$2:$B$191,Funcionarios!B55)>0,SUMIFS(Departamentos!$B:$B,Departamentos!$C:$C,Funcionarios!B55)/COUNTIF(Funcionarios!$B$2:$B$191,Funcionarios!B55)*IF(Funcionarios!G55>0,Funcionarios!G55/30,1),0) -> 0 | E65: =Funcionarios!$F55 -> 0 | F65: =Funcionarios!$E55 -> 0 | G65: =MAX(C65+D65+E65-F65,0) -> 0
A66: =Funcionarios!A56 -> 0 | B66: =Funcionarios!B56 -> 0 | C66: =(IF(AND(Funcionarios!D56>=1,COUNTIF(Funcionarios!$D$2:$D$191,">=1")>0),(Editavel!$B$17-SUM(Departamentos!$B:$B)-SUM(Funcionarios!$F$2:$F$191))*Editavel!$C$25/COUNTIF(Funcionarios!$D$2:$D$191,">=1"),0)+IF(AND(Funcionarios!D56>=2,COUNTIF(Funcionarios!$D$2:$D$191,">=2")>0),(Editavel!$B$17-SUM(Departamentos!$B:$B)-SUM(Funcionarios!$F$2:$F$191))*Editavel!$C$26/COUNTIF(Funcionarios!$D$2:$D$191,">=2"),0)+IF(AND(Funcionarios!D56>=3,COUNTIF(Funcionarios!$D$2:$D$191,">=3")>0),(Editavel!$B$17-SUM(Departamentos!$B:$B)-SUM(Funcionarios!$F$2:$F$191))*Editavel!$C$27/COUNTIF(Funcionarios!$D$2:$D$191,">=3"),0)+IF(AND(Funcionarios!D56>=4,COUNTIF(Funcionarios!$D$2:$D$191,">=4")>0),(Editavel!$B$17-SUM(Departamentos!$B:$B)-SUM(Funcionarios!$F$2:$F$191))*Editavel!$C$28/COUNTIF(Funcionarios!$D$2:$D$191,">=4"),0)+IF(AND(Funcionarios!D56>=5,COUNTIF(Funcionarios!$D$2:$D$191,">=5")>0),(Editavel!$B$17-SUM(Departamentos!$B:$B)-SUM(Funcionarios!$F$2:$F$191))*Editavel!$C$29/COUNTIF(Funcionarios!$D$2:$D$191,">=5"),0))*IF(Funcionarios!G56>0,Funcionarios!G56/30,1) -> 0 | D66: =IF(COUNTIF(Funcionarios!$B$2:$B$191,Funcionarios!B56)>0,SUMIFS(Departamentos!$B:$B,Departamentos!$C:$C,Funcionarios!B56)/COUNTIF(Funcionarios!$B$2:$B$191,Funcionarios!B56)*IF(Funcionarios!G56>0,Funcionarios!G56/30,1),0) -> 0 | E66: =Funcionarios!$F56 -> 0 | F66: =Funcionarios!$E56 -> 0 | G66: =MAX(C66+D66+E66-F66,0) -> 0
A67: =Funcionarios!A57 -> 0 | B67: =Funcionarios!B57 -> 0 | C67: =(IF(AND(Funcionarios!D57>=1,COUNTIF(Funcionarios!$D$2:$D$191,">=1")>0),(Editavel!$B$17-SUM(Departamentos!$B:$B)-SUM(Funcionarios!$F$2:$F$191))*Editavel!$C$25/COUNTIF(Funcionarios!$D$2:$D$191,">=1"),0)+IF(AND(Funcionarios!D57>=2,COUNTIF(Funcionarios!$D$2:$D$191,">=2")>0),(Editavel!$B$17-SUM(Departamentos!$B:$B)-SUM(Funcionarios!$F$2:$F$191))*Editavel!$C$26/COUNTIF(Funcionarios!$D$2:$D$191,">=2"),0)+IF(AND(Funcionarios!D57>=3,COUNTIF(Funcionarios!$D$2:$D$191,">=3")>0),(Editavel!$B$17-SUM(Departamentos!$B:$B)-SUM(Funcionarios!$F$2:$F$191))*Editavel!$C$27/COUNTIF(Funcionarios!$D$2:$D$191,">=3"),0)+IF(AND(Funcionarios!D57>=4,COUNTIF(Funcionarios!$D$2:$D$191,">=4")>0),(Editavel!$B$17-SUM(Departamentos!$B:$B)-SUM(Funcionarios!$F$2:$F$191))*Editavel!$C$28/COUNTIF(Funcionarios!$D$2:$D$191,">=4"),0)+IF(AND(Funcionarios!D57>=5,COUNTIF(Funcionarios!$D$2:$D$191,">=5")>0),(Editavel!$B$17-SUM(Departamentos!$B:$B)-SUM(Funcionarios!$F$2:$F$191))*Editavel!$C$29/COUNTIF(Funcionarios!$D$2:$D$191,">=5"),0))*IF(Funcionarios!G57>0,Funcionarios!G57/30,1) -> 0 | D67: =IF(COUNTIF(Funcionarios!$B$2:$B$191,Funcionarios!B57)>0,SUMIFS(Departamentos!$B:$B,Departamentos!$C:$C,Funcionarios!B57)/COUNTIF(Funcionarios!$B$2:$B$191,Funcionarios!B57)*IF(Funcionarios!G57>0,Funcionarios!G57/30,1),0) -> 0 | E67: =Funcionarios!$F57 -> 0 | F67: =Funcionarios!$E57 -> 0 | G67: =MAX(C67+D67+E67-F67,0) -> 0
A68: =Funcionarios!A58 -> 0 | B68: =Funcionarios!B58 -> 0 | C68: =(IF(AND(Funcionarios!D58>=1,COUNTIF(Funcionarios!$D$2:$D$191,">=1")>0),(Editavel!$B$17-SUM(Departamentos!$B:$B)-SUM(Funcionarios!$F$2:$F$191))*Editavel!$C$25/COUNTIF(Funcionarios!$D$2:$D$191,">=1"),0)+IF(AND(Funcionarios!D58>=2,COUNTIF(Funcionarios!$D$2:$D$191,">=2")>0),(Editavel!$B$17-SUM(Departamentos!$B:$B)-SUM(Funcionarios!$F$2:$F$191))*Editavel!$C$26/COUNTIF(Funcionarios!$D$2:$D$191,">=2"),0)+IF(AND(Funcionarios!D58>=3,COUNTIF(Funcionarios!$D$2:$D$191,">=3")>0),(Editavel!$B$17-SUM(Departamentos!$B:$B)-SUM(Funcionarios!$F$2:$F$191))*Editavel!$C$27/COUNTIF(Funcionarios!$D$2:$D$191,">=3"),0)+IF(AND(Funcionarios!D58>=4,COUNTIF(Funcionarios!$D$2:$D$191,">=4")>0),(Editavel!$B$17-SUM(Departamentos!$B:$B)-SUM(Funcionarios!$F$2:$F$191))*Editavel!$C$28/COUNTIF(Funcionarios!$D$2:$D$191,">=4"),0)+IF(AND(Funcionarios!D58>=5,COUNTIF(Funcionarios!$D$2:$D$191,">=5")>0),(Editavel!$B$17-SUM(Departamentos!$B:$B)-SUM(Funcionarios!$F$2:$F$191))*Editavel!$C$29/COUNTIF(Funcionarios!$D$2:$D$191,">=5"),0))*IF(Funcionarios!G58>0,Funcionarios!G58/30,1) -> 0 | D68: =IF(COUNTIF(Funcionarios!$B$2:$B$191,Funcionarios!B58)>0,SUMIFS(Departamentos!$B:$B,Departamentos!$C:$C,Funcionarios!B58)/COUNTIF(Funcionarios!$B$2:$B$191,Funcionarios!B58)*IF(Funcionarios!G58>0,Funcionarios!G58/30,1),0) -> 0 | E68: =Funcionarios!$F58 -> 0 | F68: =Funcionarios!$E58 -> 0 | G68: =MAX(C68+D68+E68-F68,0) -> 0
... A202: =Funcionarios!A192 -> 0 | B202: =Funcionarios!B192 -> 0 | C202: =(IF(AND(Funcionarios!D192>=1,COUNTIF(Funcionarios!$D$2:$D$191,">=1")>0),(Editavel!$B$17-SUM(Departamentos!$B:$B)-SUM(Funcionarios!$F$2:$F$191))*Editavel!$C$25/COUNTIF(Funcionarios!$D$2:$D$191,">=1"),0)+IF(AND(Funcionarios!D192>=2,COUNTIF(Funcionarios!$D$2:$D$191,">=2")>0),(Editavel!$B$17-SUM(Departamentos!$B:$B)-SUM(Funcionarios!$F$2:$F$191))*Editavel!$C$26/COUNTIF(Funcionarios!$D$2:$D$191,">=2"),0)+IF(AND(Funcionarios!D192>=3,COUNTIF(Funcionarios!$D$2:$D$191,">=3")>0),(Editavel!$B$17-SUM(Departamentos!$B:$B)-SUM(Funcionarios!$F$2:$F$191))*Editavel!$C$27/COUNTIF(Funcionarios!$D$2:$D$191,">=3"),0)+IF(AND(Funcionarios!D192>=4,COUNTIF(Funcionarios!$D$2:$D$191,">=4")>0),(Editavel!$B$17-SUM(Departamentos!$B:$B)-SUM(Funcionarios!$F$2:$F$191))*Editavel!$C$28/COUNTIF(Funcionarios!$D$2:$D$191,">=4"),0)+IF(AND(Funcionarios!D192>=5,COUNTIF(Funcionarios!$D$2:$D$191,">=5")>0),(Editavel!$B$17-SUM(Departamentos!$B:$B)-SUM(Funcionarios!$F$2:$F$191))*Editavel!$C$29/COUNTIF(Funcionarios!$D$2:$D$191,">=5"),0))*IF(Funcionarios!G192>0,Funcionarios!G192/30,1) -> 0 | D202: =IF(COUNTIF(Funcionarios!$B$2:$B$191,Funcionarios!B192)>0,SUMIFS(Departamentos!$B:$B,Departamentos!$C:$C,Funcionarios!B192)/COUNTIF(Funcionarios!$B$2:$B$191,Funcionarios!B192)*IF(Funcionarios!G192>0,Funcionarios!G192/30,1),0) -> 0 | E202: =Funcionarios!$F192 -> 0 | F202: =Funcionarios!$E192 -> 0 | G202: =MAX(C202+D202+E202-F202,0) -> 0
